
```bash
2021-02-28 19:12:34.443 169346 WARNING ironic.drivers.modules.redfish.utils [req-18e1c38d-6ebe-45d8-bde1-c3da4c114f1c - - - - -] For node 1d4cc130-187a-4afd-87f8-cae3f1dc6796, got a connection error from Redfish at address "https://192.168.122.1:6233" using auth type "auto". Error: Unable to connect to https://192.168.122.1:6233/redfish/v1/. Error: HTTPSConnectionPool(host='192.168.122.1', port=6233): Max retries exceeded with url: /redfish/v1/ (Caused by NewConnectionError('<urllib3.connection.HTTPSConnection object at 0x7f21dd534be0>: Failed to establish a new connection: [Errno 110] ETIMEDOUT')): sushy.exceptions.ConnectionError: Unable to connect to https://192.168.122.1:6233/redfish/v1/. Error: HTTPSConnectionPool(host='192.168.122.1', port=6233): Max retries exceeded with url: /redfish/v1/ (Caused by NewConnectionError('<urllib3.connection.HTTPSConnection object at 0x7f21dd534be0>: Failed to establish a new connection: [Errno 110] ETIMEDOUT'))
2021-02-28 19:12:38.459 169346 DEBUG sushy.connector [req-18e1c38d-6ebe-45d8-bde1-c3da4c114f1c - - - - -] HTTP request: GET https://192.168.122.1:6233/redfish/v1/; headers: {'OData-Version': '4.0'}; body: None; blocking: False; timeout: 60; session arguments: {}; _op /home/tan/ws/poc/rs/_ironic/ironic/.tox/venv/lib/python3.8/site-packages/sushy/connector.py:95
2021-02-28 19:12:40.213 169346 DEBUG futurist.periodics [-] Submitting periodic callback 'ironic.conductor.manager.ConductorManager._sync_local_state' _process_scheduled /home/tan/ws/poc/rs/_ironic/ironic/.tox/venv/lib/python3.8/site-packages/futurist/periodics.py:641

```